<?xml version="1.0"?>
<mujocoinclude>
  <body name="dClaw" euler="3.14 0 0" childclass="dclaw3xh">
    <geom mesh="acrylic_circle"  name="base_plate" material="acrylic_circle_mat"/>
    <geom class="phy_metal" type="cylinder" size="0.075 0.004" mass=".11" />
    <site name="S_grasp" pos="0 0 0.24" type="sphere" size="0.01" group="4"/>


    <!-- INDEX/FIRST FINGER -->
    <body name="FFbase" pos=".03 -0.052 .020" euler="0 0 .52">


      <geom name="FFbase_xh28" mesh="xh28" pos="0 0 0.01425" euler="1.57 0 1.57" material="FFbase_xh28_mat"/>
      <geom class="phy_metal" type="box" pos=".012 0 0.014" size="0.024 0.0175 0.015" mass=".093" />


      <body name="FF10" pos="0 0 0.01425" euler="0 0 3.14">
        <geom name="FF10_metal_clamping"        mesh="metal_clamping"                       euler="0 0 1.57"    material="FF10_metal_clamping_mat"/>
        <geom name="FF10_metal_clamping_small"  mesh="metal_clamping_small" pos="0 0 0.055" euler="3.14 0 0"    material="FF10_metal_clamping_small_mat"/>
        <geom name="FF10_xh28"                  mesh="xh28"                 pos="0 0 0.068" euler="1.57 1.57 0" material="FF10_xh28_mat"/>
        <geom class="phy_metal" type="box" pos="0 0 0.056" size="0.0175 0.015 0.024" mass=".093"     />
        <geom class="phy_metal" type="box" pos="0.0 0 0.026" size="0.0125 0.0214 0.003" mass=".003"  />
        <geom class="phy_metal" type="box" pos="0 0.02 0.013" size="0.011 0.0012 0.016" mass=".002"  />
        <geom class="phy_metal" type="box" pos="0 -0.02 0.013" size="0.011 0.0012 0.016" mass=".002" />
        <geom class="phy_metal" type="box" pos="0 0 0.033" size="0.019 0.014 0.006" mass=".005"      />
        <joint name="FFJ10" type="hinge" axis="0 1 0" range="-1.57 1.57"/>
        <body name="FFL11" pos="0 0 0.0675">
          <geom name="FFL11_metal_clamping_small" mesh="metal_clamping_small" pos="0 0 0.055"   euler="3.14 0 0"    material="FFL11_metal_clamping_small_mat"/>
          <geom name="FFL11_xh28"                 mesh="xh28"                 pos="0 0 0.0686"  euler="1.57 1.57 0" material="FFL11_xh28_mat"/>
          <geom name="FFL11_metal_clamping"       mesh="metal_clamping"                                             material="FFL11_metal_clamping_mat"/>
          <geom class="phy_metal" type="box" pos="0 0 0.056" size="0.0175 0.015 0.024" mass=".093"     />
          <geom class="phy_metal" type="box" pos="0 0 0.026" size="0.0214 0.0125 0.003" mass=".003"    />
          <geom class="phy_metal" type="box" pos="0.02 0 0.013" size="0.0012 0.011 0.016" mass=".002"  />
          <geom class="phy_metal" type="box" pos="-0.02 0 0.013" size="0.0012 0.011 0.016" mass=".002" />
          <geom class="phy_metal" type="box" pos="0 0 0.033" size="0.019 0.014 0.006" mass=".005"      />
          <joint name="FFJ11" type="hinge" axis="1 0 0" range="-1.57 1.57"/>
          <body name="FFL12" pos="0 0 0.068">
            <geom name="FFL12_metal_clamping" mesh="metal_clamping"                 material="FFL12_metal_clamping_mat"/>
            <!-- <geom name="FFL12_plastic_finger" mesh="plastic_finger" pos="0 0 0.046" material="FFL12_plastic_finger_mat"/> -->
            <geom name="FFL12_plastic_finger"     mesh="finger_for_optoforce" pos="0 0 0.0274"  euler="0 0 1.57" material="FFL12_plastic_finger_mat"/>
            <geom name="FFL12_optoforce_sensor"   mesh="optoforce_sensor"     pos="0 0 0.0671"  euler="0 0 1.57" material="FFL12_optoforce_sensor_mat"/>
            <geom name="FFL12_optoforce_base"     mesh="optoforce_base"       pos="0 0 0.0671"  euler="0 0 1.57" material="FFL12_optoforce_base_mat"/>

            <geom     class="phy_metal"   type="box" pos="0.0 0 0.026"    size="0.0214 0.0125 0.003"  mass=".003" />
            <geom     class="phy_metal"   type="box" pos="0.02 0 0.013"   size="0.0012 0.011 0.016"   mass=".002" />
            <geom     class="phy_metal"   type="box" pos="-0.02 0 0.013"  size="0.0012 0.011 0.016"   mass=".002"/>

            <body name="FFL12_tip" pos="0 0 0">
                <geom class="phy_plastic" type="box"       pos="0 0 0.03"   size="0.0245 0.014 0.003"  mass=".007"/>
                <geom class="phy_plastic" type="cylinder"  pos="0 0 0.0531" size="0.01156 0.02"          mass=".009"/>
                <body name="FFL12_optoforce" pos="0 0 0.073">
                    <geom class="phy_optoforce"  name="FFL12_phy_optoforce"/>
                    <site class="site_optoforce" name="FFL12_site_optoforce"/>
                </body>
            </body>

            <joint name="FFJ12" type="hinge" axis="1 0 0" range="-1.57 1.57"/>
          </body>
        </body>
      </body>
    </body>
    <!-- MIDDLE FINGER -->
    <body name="MFbase" pos=".03 0.052 .020" euler="0 0 2.6">
      <geom name="MFbase_xh28" mesh="xh28" pos="0 0 0.01425" euler="1.57 0 1.57"  material="MFbase_xh28_mat"/>
      <geom class="phy_metal" type="box" pos=".012 0 0.014" size="0.024 0.0175 0.015" mass=".093" />
      <body name="MF20" pos="0 0 0.01425" euler="0 0 3.14">
        <geom name="MF20_metal_clamping"        mesh="metal_clamping"                       euler="0 0 1.57"    material="MF20_metal_clamping_mat"/>
        <geom name="MF20_metal_clamping_small"  mesh="metal_clamping_small" pos="0 0 0.055" euler="3.14 0 0"    material="MF20_metal_clamping_small_mat"/>
        <geom name="MF20_xh28"                  mesh="xh28"                 pos="0 0 0.068" euler="1.57 1.57 0" material="MF20_xh28_mat"/>
        <geom class="phy_metal" type="box" pos="0 0 0.056" size="0.0175 0.015 0.024" mass=".093"     />
        <geom class="phy_metal" type="box" pos="0.0 0 0.026" size="0.0125 0.0214 0.003" mass=".003"  />
        <geom class="phy_metal" type="box" pos="0 0.02 0.013" size="0.011 0.0012 0.016" mass=".002"  />
        <geom class="phy_metal" type="box" pos="0 -0.02 0.013" size="0.011 0.0012 0.016" mass=".002" />
        <geom class="phy_metal" type="box" pos="0 0 0.033" size="0.019 0.014 0.006" mass=".005"      />
        <joint name="MFJ20" type="hinge" axis="0 1 0" range="-1.57 1.57"/>
        <body name="MFL21" pos="0 0 0.0675">
          <geom name="MFL21_metal_clamping_small" mesh="metal_clamping_small" pos="0 0 0.055"   euler="3.14 0 0"    material="MFL21_metal_clamping_small_mat"/>
          <geom name="MFL21_xh28"                 mesh="xh28"                 pos="0 0 0.0686"  euler="1.57 1.57 0" material="MFL21_xh28_mat"/>
          <geom name="MFL21_metal_clamping"       mesh="metal_clamping"                                             material="MFL21_metal_clamping_mat"/>
          <geom class="phy_metal" type="box" pos="0 0 0.056" size="0.0175 0.015 0.024" mass=".093"     />
          <geom class="phy_metal" type="box" pos="0 0 0.026" size="0.0214 0.0125 0.003" mass=".003"    />
          <geom class="phy_metal" type="box" pos="0.02 0 0.013" size="0.0012 0.011 0.016" mass=".002"  />
          <geom class="phy_metal" type="box" pos="-0.02 0 0.013" size="0.0012 0.011 0.016" mass=".002" />
          <geom class="phy_metal" type="box" pos="0 0 0.033" size="0.019 0.014 0.006" mass=".005"      />
          <joint name="MFJ21" type="hinge" axis="1 0 0" range="-1.57 1.57"/>
          <body name="MFL22" pos="0 0 0.068">
            <geom name="MFL22_metal_clamping" mesh="metal_clamping"                 material="MFL22_metal_clamping_mat"/>
            <!-- <geom name="MFL22_plastic_finger" mesh="plastic_finger" pos="0 0 0.046" material="MFL22_plastic_finger_mat"/> -->
            <geom name="MFL22_plastic_finger" mesh="finger_for_optoforce" pos="0 0 0.0274" euler="0 0 1.57" material="MFL22_plastic_finger_mat"/>
            <geom name="MFL22_optoforce_sensor"   mesh="optoforce_sensor"     pos="0 0 0.0671"  euler="0 0 1.57" material="MFL22_optoforce_sensor_mat"/>
            <geom name="MFL22_optoforce_base"     mesh="optoforce_base"       pos="0 0 0.0671"  euler="0 0 1.57" material="MFL22_optoforce_base_mat"/>

            <geom class="phy_metal" type="box" pos="0.0 0 0.026" size="0.0214 0.0125 0.003" mass=".003" />
            <geom class="phy_metal" type="box" pos="0.02 0 0.013" size="0.0012 0.011 0.016" mass=".002" />
            <geom class="phy_metal" type="box" pos="-0.02 0 0.013" size="0.0012 0.011 0.016" mass=".002"/>

            <body name="MFL22_tip" pos="0 0 0">
                <geom class="phy_plastic" type="box"       pos="0 0 0.03"   size="0.0245 0.014 0.003"  mass=".007"/>
                <geom class="phy_plastic" type="cylinder"  pos="0 0 0.0531" size="0.01156 0.02"          mass=".009"/>
                <body name="MFL22_optoforce" pos="0 0 0.073">
                    <geom class="phy_optoforce"  name="MFL22_phy_optoforce"/>
                    <site class="site_optoforce" name="MFL22_site_optoforce"/>
                </body>
            </body>

            <joint name="MFJ22" type="hinge" axis="1 0 0" range="-1.57 1.57"/>
          </body>
        </body>
      </body>
    </body>
    <!-- THUMB -->
    <body name="THbase" pos="-.06 0 .020" euler="0 0 -1.57">
      <geom name="THbase_xh28" mesh="xh28" pos="0 0 0.01425" euler="1.57 0 1.57" material="THbase_xh28_mat"/>
      <geom class="phy_metal" type="box" pos=".012 0 0.014" size="0.024 0.0175 0.015" mass=".093" />
      <body name="TH30" pos="0 0 0.01425" euler="0 0 3.14">
        <geom name="TH30_metal_clamping"        mesh="metal_clamping"                       euler="0 0 1.57"    material="TH30_metal_clamping_mat"/>
        <geom name="TH30_metal_clamping_small"  mesh="metal_clamping_small" pos="0 0 0.055" euler="3.14 0 0"    material="TH30_metal_clamping_small_mat"/>
        <geom name="TH30_xh28"                  mesh="xh28"                 pos="0 0 0.068" euler="1.57 1.57 0" material="TH30_xh28_mat"/>
        <geom class="phy_metal" type="box" pos="0 0 0.056" size="0.0175 0.015 0.024" mass=".093"     />
        <geom class="phy_metal" type="box" pos="0.0 0 0.026" size="0.0125 0.0214 0.003" mass=".003"  />
        <geom class="phy_metal" type="box" pos="0 0.02 0.013" size="0.011 0.0012 0.016" mass=".002"  />
        <geom class="phy_metal" type="box" pos="0 -0.02 0.013" size="0.011 0.0012 0.016" mass=".002" />
        <geom class="phy_metal" type="box" pos="0 0 0.033" size="0.019 0.014 0.006" mass=".005"      />
        <joint name="THJ30" type="hinge" axis="0 1 0" range="-1.57 1.57"/>
        <body name="THL31" pos="0 0 0.0675">
          <geom name="THL31_metal_clamping_small" mesh="metal_clamping_small" pos="0 0 0.055"   euler="3.14 0 0"    material="THL31_metal_clamping_small_mat"/>
          <geom name="THL31_xh28"                 mesh="xh28"                 pos="0 0 0.0686"  euler="1.57 1.57 0" material="THL31_xh28_mat"/>
          <geom name="THL31_metal_clamping"       mesh="metal_clamping"                                             material="THL31_metal_clamping_mat"/>
          <geom class="phy_metal" type="box" pos="0 0 0.056" size="0.0175 0.015 0.024" mass=".093"    />
          <geom class="phy_metal" type="box" pos="0 0 0.026" size="0.0214 0.0125 0.003" mass=".003"   />
          <geom class="phy_metal" type="box" pos="0.02 0 0.013" size="0.0012 0.011 0.016" mass=".002" />
          <geom class="phy_metal" type="box" pos="-0.02 0 0.013" size="0.0012 0.011 0.016" mass=".002"/>
          <geom class="phy_metal" type="box" pos="0 0 0.033" size="0.019 0.014 0.006" mass=".005"     />
          <joint name="THJ31" type="hinge" axis="1 0 0" range="-1.57 1.57"/>
          <body name="THL32" pos="0 0 0.068">
            <geom name="THL32_metal_clamping" mesh="metal_clamping"                 material="THL32_metal_clamping_mat"/>
            <!-- <geom name="THL32_plastic_finger" mesh="plastic_finger" pos="0 0 0.046" material="THL32_plastic_finger_mat"/> -->
            <geom name="THL32_plastic_finger"     mesh="finger_for_optoforce" pos="0 0 0.0274" euler="0 0 1.57" material="THL32_plastic_finger_mat"/>
            <geom name="THL32_optoforce_sensor"   mesh="optoforce_sensor"     pos="0 0 0.0671"  euler="0 0 1.57" material="THL32_optoforce_sensor_mat"/>
            <geom name="THL32_optoforce_base"     mesh="optoforce_base"       pos="0 0 0.0671"  euler="0 0 1.57" material="THL32_optoforce_base_mat"/>
            <geom class="phy_metal" type="box" pos="0.0 0 0.026" size="0.0214 0.0125 0.003" mass=".003" />
            <geom class="phy_metal" type="box" pos="0.02 0 0.013" size="0.0012 0.011 0.016" mass=".002" />
            <geom class="phy_metal" type="box" pos="-0.02 0 0.013" size="0.0012 0.011 0.016" mass=".002"/>

            <body name="THL32_tip" pos="0 0 0">
                <geom class="phy_plastic" type="box"       pos="0 0 0.03"   size="0.0245 0.014 0.003"  mass=".007"/>
                <geom class="phy_plastic" type="cylinder"  pos="0 0 0.0531" size="0.01156 0.02"          mass=".009"/>
                <body name="THL32_optoforce" pos="0 0 0.073">
                    <geom class="phy_optoforce"  name="THL32_phy_optoforce"/>
                    <site class="site_optoforce" name="THL32_site_optoforce"/>
                </body>
            </body>

            <joint name="THJ32" type="hinge" axis="1 0 0" range="-1.57 1.57"/>
          </body>
        </body>
      </body>
    </body>
  </body>
</mujocoinclude>